{
 "cells": [
  {
   "cell_type": "code",
   "execution_count": null,
   "id": "2f9dde4d",
   "metadata": {},
   "outputs": [
    {
     "name": "stdout",
     "output_type": "stream",
     "text": [
      "Model: \"sequential\"\n",
      "_________________________________________________________________\n",
      "Layer (type)                 Output Shape              Param #   \n",
      "=================================================================\n",
      "conv2d (Conv2D)              (None, 24, 24, 32)        832       \n",
      "_________________________________________________________________\n",
      "max_pooling2d (MaxPooling2D) (None, 12, 12, 32)        0         \n",
      "_________________________________________________________________\n",
      "dropout (Dropout)            (None, 12, 12, 32)        0         \n",
      "_________________________________________________________________\n",
      "conv2d_1 (Conv2D)            (None, 8, 8, 64)          51264     \n",
      "_________________________________________________________________\n",
      "max_pooling2d_1 (MaxPooling2 (None, 4, 4, 64)          0         \n",
      "_________________________________________________________________\n",
      "dropout_1 (Dropout)          (None, 4, 4, 64)          0         \n",
      "_________________________________________________________________\n",
      "flatten (Flatten)            (None, 1024)              0         \n",
      "_________________________________________________________________\n",
      "dense (Dense)                (None, 128)               131200    \n",
      "_________________________________________________________________\n",
      "dense_1 (Dense)              (None, 10)                1290      \n",
      "=================================================================\n",
      "Total params: 184,586\n",
      "Trainable params: 184,586\n",
      "Non-trainable params: 0\n",
      "_________________________________________________________________\n",
      "Train on 60000 samples\n",
      "Epoch 1/4\n",
      "60000/60000 [==============================] - 33s 557us/sample - loss: 0.2595 - accuracy: 0.9180\n",
      "Epoch 2/4\n",
      "60000/60000 [==============================] - 31s 523us/sample - loss: 0.0790 - accuracy: 0.9752\n",
      "Epoch 3/4\n",
      "60000/60000 [==============================] - 32s 537us/sample - loss: 0.0579 - accuracy: 0.9815\n",
      "Epoch 4/4\n",
      "60000/60000 [==============================] - 32s 536us/sample - loss: 0.0488 - accuracy: 0.9844- loss: 0.0484  - ETA: 0s - loss:\n",
      "Test loss: 0.027273815253854264\n",
      "Test accuracy: 0.9915\n"
     ]
    },
    {
     "name": "stderr",
     "output_type": "stream",
     "text": [
      "ERROR:root:Internal Python error in the inspect module.\n",
      "Below is the traceback from this internal error.\n",
      "\n",
      "ERROR:root:Internal Python error in the inspect module.\n",
      "Below is the traceback from this internal error.\n",
      "\n",
      "ERROR:root:Internal Python error in the inspect module.\n",
      "Below is the traceback from this internal error.\n",
      "\n"
     ]
    },
    {
     "name": "stdout",
     "output_type": "stream",
     "text": [
      "Traceback (most recent call last):\n",
      "  File \"C:\\Users\\arisj\\anaconda3\\envs\\CPE 4903\\lib\\site-packages\\IPython\\core\\interactiveshell.py\", line 3444, in run_code\n",
      "    exec(code_obj, self.user_global_ns, self.user_ns)\n",
      "  File \"C:\\Users\\arisj\\AppData\\Local\\Temp/ipykernel_7724/233499380.py\", line 48, in <module>\n",
      "    model.save(r\"/home/pi/CPE4903/digit_recog.h5\")\n",
      "  File \"C:\\Users\\arisj\\anaconda3\\envs\\CPE 4903\\lib\\site-packages\\tensorflow_core\\python\\keras\\engine\\network.py\", line 1008, in save\n",
      "    signatures, options)\n",
      "  File \"C:\\Users\\arisj\\anaconda3\\envs\\CPE 4903\\lib\\site-packages\\tensorflow_core\\python\\keras\\saving\\save.py\", line 112, in save_model\n",
      "    model, filepath, overwrite, include_optimizer)\n",
      "  File \"C:\\Users\\arisj\\anaconda3\\envs\\CPE 4903\\lib\\site-packages\\tensorflow_core\\python\\keras\\saving\\hdf5_format.py\", line 92, in save_model_to_hdf5\n",
      "    f = h5py.File(filepath, mode='w')\n",
      "  File \"C:\\Users\\arisj\\anaconda3\\envs\\CPE 4903\\lib\\site-packages\\h5py\\_hl\\files.py\", line 312, in __init__\n",
      "    fid = make_fid(name, mode, userblock_size, fapl, swmr=swmr)\n",
      "  File \"C:\\Users\\arisj\\anaconda3\\envs\\CPE 4903\\lib\\site-packages\\h5py\\_hl\\files.py\", line 148, in make_fid\n",
      "    fid = h5f.create(name, h5f.ACC_TRUNC, fapl=fapl, fcpl=fcpl)\n",
      "  File \"h5py\\_objects.pyx\", line 54, in h5py._objects.with_phil.wrapper\n",
      "  File \"h5py\\_objects.pyx\", line 55, in h5py._objects.with_phil.wrapper\n",
      "  File \"h5py\\h5f.pyx\", line 98, in h5py.h5f.create\n",
      "OSError: Unable to create file (unable to open file: name = '/home/pi/CPE4903/digit_recog.h5', errno = 2, error message = 'No such file or directory', flags = 13, o_flags = 302)\n",
      "\n",
      "During handling of the above exception, another exception occurred:\n",
      "\n",
      "Traceback (most recent call last):\n",
      "  File \"C:\\Users\\arisj\\anaconda3\\envs\\CPE 4903\\lib\\site-packages\\IPython\\core\\interactiveshell.py\", line 2064, in showtraceback\n",
      "    stb = value._render_traceback_()\n",
      "AttributeError: 'OSError' object has no attribute '_render_traceback_'\n",
      "\n",
      "During handling of the above exception, another exception occurred:\n",
      "\n",
      "Traceback (most recent call last):\n",
      "  File \"C:\\Users\\arisj\\anaconda3\\envs\\CPE 4903\\lib\\site-packages\\IPython\\core\\ultratb.py\", line 1101, in get_records\n",
      "    return _fixed_getinnerframes(etb, number_of_lines_of_context, tb_offset)\n",
      "  File \"C:\\Users\\arisj\\anaconda3\\envs\\CPE 4903\\lib\\site-packages\\IPython\\core\\ultratb.py\", line 248, in wrapped\n",
      "    return f(*args, **kwargs)\n",
      "  File \"C:\\Users\\arisj\\anaconda3\\envs\\CPE 4903\\lib\\site-packages\\IPython\\core\\ultratb.py\", line 281, in _fixed_getinnerframes\n",
      "    records = fix_frame_records_filenames(inspect.getinnerframes(etb, context))\n",
      "  File \"C:\\Users\\arisj\\anaconda3\\envs\\CPE 4903\\lib\\inspect.py\", line 1502, in getinnerframes\n",
      "    frameinfo = (tb.tb_frame,) + getframeinfo(tb, context)\n",
      "  File \"C:\\Users\\arisj\\anaconda3\\envs\\CPE 4903\\lib\\inspect.py\", line 1460, in getframeinfo\n",
      "    filename = getsourcefile(frame) or getfile(frame)\n",
      "  File \"C:\\Users\\arisj\\anaconda3\\envs\\CPE 4903\\lib\\inspect.py\", line 696, in getsourcefile\n",
      "    if getattr(getmodule(object, filename), '__loader__', None) is not None:\n",
      "  File \"C:\\Users\\arisj\\anaconda3\\envs\\CPE 4903\\lib\\inspect.py\", line 733, in getmodule\n",
      "    if ismodule(module) and hasattr(module, '__file__'):\n",
      "  File \"C:\\Users\\arisj\\anaconda3\\envs\\CPE 4903\\lib\\site-packages\\tensorflow\\__init__.py\", line 50, in __getattr__\n",
      "    module = self._load()\n",
      "  File \"C:\\Users\\arisj\\anaconda3\\envs\\CPE 4903\\lib\\site-packages\\tensorflow\\__init__.py\", line 44, in _load\n",
      "    module = _importlib.import_module(self.__name__)\n",
      "  File \"C:\\Users\\arisj\\anaconda3\\envs\\CPE 4903\\lib\\importlib\\__init__.py\", line 127, in import_module\n",
      "    return _bootstrap._gcd_import(name[level:], package, level)\n",
      "  File \"<frozen importlib._bootstrap>\", line 1006, in _gcd_import\n",
      "  File \"<frozen importlib._bootstrap>\", line 983, in _find_and_load\n",
      "  File \"<frozen importlib._bootstrap>\", line 965, in _find_and_load_unlocked\n",
      "ModuleNotFoundError: No module named 'tensorflow_core.estimator'\n",
      "Traceback (most recent call last):\n",
      "  File \"C:\\Users\\arisj\\anaconda3\\envs\\CPE 4903\\lib\\site-packages\\IPython\\core\\interactiveshell.py\", line 3444, in run_code\n",
      "    exec(code_obj, self.user_global_ns, self.user_ns)\n",
      "  File \"C:\\Users\\arisj\\AppData\\Local\\Temp/ipykernel_7724/233499380.py\", line 48, in <module>\n",
      "    model.save(r\"/home/pi/CPE4903/digit_recog.h5\")\n",
      "  File \"C:\\Users\\arisj\\anaconda3\\envs\\CPE 4903\\lib\\site-packages\\tensorflow_core\\python\\keras\\engine\\network.py\", line 1008, in save\n",
      "    signatures, options)\n",
      "  File \"C:\\Users\\arisj\\anaconda3\\envs\\CPE 4903\\lib\\site-packages\\tensorflow_core\\python\\keras\\saving\\save.py\", line 112, in save_model\n",
      "    model, filepath, overwrite, include_optimizer)\n",
      "  File \"C:\\Users\\arisj\\anaconda3\\envs\\CPE 4903\\lib\\site-packages\\tensorflow_core\\python\\keras\\saving\\hdf5_format.py\", line 92, in save_model_to_hdf5\n",
      "    f = h5py.File(filepath, mode='w')\n",
      "  File \"C:\\Users\\arisj\\anaconda3\\envs\\CPE 4903\\lib\\site-packages\\h5py\\_hl\\files.py\", line 312, in __init__\n",
      "    fid = make_fid(name, mode, userblock_size, fapl, swmr=swmr)\n",
      "  File \"C:\\Users\\arisj\\anaconda3\\envs\\CPE 4903\\lib\\site-packages\\h5py\\_hl\\files.py\", line 148, in make_fid\n",
      "    fid = h5f.create(name, h5f.ACC_TRUNC, fapl=fapl, fcpl=fcpl)\n",
      "  File \"h5py\\_objects.pyx\", line 54, in h5py._objects.with_phil.wrapper\n",
      "  File \"h5py\\_objects.pyx\", line 55, in h5py._objects.with_phil.wrapper\n",
      "  File \"h5py\\h5f.pyx\", line 98, in h5py.h5f.create\n",
      "OSError: Unable to create file (unable to open file: name = '/home/pi/CPE4903/digit_recog.h5', errno = 2, error message = 'No such file or directory', flags = 13, o_flags = 302)\n",
      "\n",
      "During handling of the above exception, another exception occurred:\n",
      "\n",
      "Traceback (most recent call last):\n",
      "  File \"C:\\Users\\arisj\\anaconda3\\envs\\CPE 4903\\lib\\site-packages\\IPython\\core\\interactiveshell.py\", line 2064, in showtraceback\n",
      "    stb = value._render_traceback_()\n",
      "AttributeError: 'OSError' object has no attribute '_render_traceback_'\n",
      "\n",
      "During handling of the above exception, another exception occurred:\n",
      "\n",
      "Traceback (most recent call last):\n",
      "  File \"C:\\Users\\arisj\\anaconda3\\envs\\CPE 4903\\lib\\site-packages\\IPython\\core\\interactiveshell.py\", line 3364, in run_ast_nodes\n",
      "    if (await self.run_code(code, result,  async_=asy)):\n",
      "  File \"C:\\Users\\arisj\\anaconda3\\envs\\CPE 4903\\lib\\site-packages\\IPython\\core\\interactiveshell.py\", line 3461, in run_code\n",
      "    self.showtraceback(running_compiled_code=True)\n",
      "  File \"C:\\Users\\arisj\\anaconda3\\envs\\CPE 4903\\lib\\site-packages\\IPython\\core\\interactiveshell.py\", line 2067, in showtraceback\n",
      "    value, tb, tb_offset=tb_offset)\n",
      "  File \"C:\\Users\\arisj\\anaconda3\\envs\\CPE 4903\\lib\\site-packages\\IPython\\core\\ultratb.py\", line 1368, in structured_traceback\n",
      "    self, etype, value, tb, tb_offset, number_of_lines_of_context)\n",
      "  File \"C:\\Users\\arisj\\anaconda3\\envs\\CPE 4903\\lib\\site-packages\\IPython\\core\\ultratb.py\", line 1268, in structured_traceback\n",
      "    self, etype, value, tb, tb_offset, number_of_lines_of_context\n",
      "  File \"C:\\Users\\arisj\\anaconda3\\envs\\CPE 4903\\lib\\site-packages\\IPython\\core\\ultratb.py\", line 1125, in structured_traceback\n",
      "    tb_offset)\n",
      "  File \"C:\\Users\\arisj\\anaconda3\\envs\\CPE 4903\\lib\\site-packages\\IPython\\core\\ultratb.py\", line 1082, in format_exception_as_a_whole\n",
      "    last_unique, recursion_repeat = find_recursion(orig_etype, evalue, records)\n",
      "  File \"C:\\Users\\arisj\\anaconda3\\envs\\CPE 4903\\lib\\site-packages\\IPython\\core\\ultratb.py\", line 382, in find_recursion\n",
      "    return len(records), 0\n",
      "TypeError: object of type 'NoneType' has no len()\n",
      "\n",
      "During handling of the above exception, another exception occurred:\n",
      "\n",
      "Traceback (most recent call last):\n",
      "  File \"C:\\Users\\arisj\\anaconda3\\envs\\CPE 4903\\lib\\site-packages\\IPython\\core\\interactiveshell.py\", line 2064, in showtraceback\n",
      "    stb = value._render_traceback_()\n",
      "AttributeError: 'TypeError' object has no attribute '_render_traceback_'\n",
      "\n",
      "During handling of the above exception, another exception occurred:\n",
      "\n",
      "Traceback (most recent call last):\n",
      "  File \"C:\\Users\\arisj\\anaconda3\\envs\\CPE 4903\\lib\\site-packages\\IPython\\core\\ultratb.py\", line 1101, in get_records\n",
      "    return _fixed_getinnerframes(etb, number_of_lines_of_context, tb_offset)\n",
      "  File \"C:\\Users\\arisj\\anaconda3\\envs\\CPE 4903\\lib\\site-packages\\IPython\\core\\ultratb.py\", line 248, in wrapped\n",
      "    return f(*args, **kwargs)\n",
      "  File \"C:\\Users\\arisj\\anaconda3\\envs\\CPE 4903\\lib\\site-packages\\IPython\\core\\ultratb.py\", line 281, in _fixed_getinnerframes\n",
      "    records = fix_frame_records_filenames(inspect.getinnerframes(etb, context))\n",
      "  File \"C:\\Users\\arisj\\anaconda3\\envs\\CPE 4903\\lib\\inspect.py\", line 1502, in getinnerframes\n",
      "    frameinfo = (tb.tb_frame,) + getframeinfo(tb, context)\n",
      "  File \"C:\\Users\\arisj\\anaconda3\\envs\\CPE 4903\\lib\\inspect.py\", line 1460, in getframeinfo\n",
      "    filename = getsourcefile(frame) or getfile(frame)\n",
      "  File \"C:\\Users\\arisj\\anaconda3\\envs\\CPE 4903\\lib\\inspect.py\", line 696, in getsourcefile\n",
      "    if getattr(getmodule(object, filename), '__loader__', None) is not None:\n",
      "  File \"C:\\Users\\arisj\\anaconda3\\envs\\CPE 4903\\lib\\inspect.py\", line 733, in getmodule\n",
      "    if ismodule(module) and hasattr(module, '__file__'):\n",
      "  File \"C:\\Users\\arisj\\anaconda3\\envs\\CPE 4903\\lib\\site-packages\\tensorflow\\__init__.py\", line 50, in __getattr__\n",
      "    module = self._load()\n",
      "  File \"C:\\Users\\arisj\\anaconda3\\envs\\CPE 4903\\lib\\site-packages\\tensorflow\\__init__.py\", line 44, in _load\n",
      "    module = _importlib.import_module(self.__name__)\n",
      "  File \"C:\\Users\\arisj\\anaconda3\\envs\\CPE 4903\\lib\\importlib\\__init__.py\", line 127, in import_module\n",
      "    return _bootstrap._gcd_import(name[level:], package, level)\n",
      "  File \"<frozen importlib._bootstrap>\", line 1006, in _gcd_import\n",
      "  File \"<frozen importlib._bootstrap>\", line 983, in _find_and_load\n",
      "  File \"<frozen importlib._bootstrap>\", line 965, in _find_and_load_unlocked\n",
      "ModuleNotFoundError: No module named 'tensorflow_core.estimator'\n",
      "Traceback (most recent call last):\n",
      "  File \"C:\\Users\\arisj\\anaconda3\\envs\\CPE 4903\\lib\\site-packages\\IPython\\core\\interactiveshell.py\", line 3444, in run_code\n",
      "    exec(code_obj, self.user_global_ns, self.user_ns)\n",
      "  File \"C:\\Users\\arisj\\AppData\\Local\\Temp/ipykernel_7724/233499380.py\", line 48, in <module>\n",
      "    model.save(r\"/home/pi/CPE4903/digit_recog.h5\")\n",
      "  File \"C:\\Users\\arisj\\anaconda3\\envs\\CPE 4903\\lib\\site-packages\\tensorflow_core\\python\\keras\\engine\\network.py\", line 1008, in save\n",
      "    signatures, options)\n",
      "  File \"C:\\Users\\arisj\\anaconda3\\envs\\CPE 4903\\lib\\site-packages\\tensorflow_core\\python\\keras\\saving\\save.py\", line 112, in save_model\n",
      "    model, filepath, overwrite, include_optimizer)\n",
      "  File \"C:\\Users\\arisj\\anaconda3\\envs\\CPE 4903\\lib\\site-packages\\tensorflow_core\\python\\keras\\saving\\hdf5_format.py\", line 92, in save_model_to_hdf5\n",
      "    f = h5py.File(filepath, mode='w')\n",
      "  File \"C:\\Users\\arisj\\anaconda3\\envs\\CPE 4903\\lib\\site-packages\\h5py\\_hl\\files.py\", line 312, in __init__\n",
      "    fid = make_fid(name, mode, userblock_size, fapl, swmr=swmr)\n",
      "  File \"C:\\Users\\arisj\\anaconda3\\envs\\CPE 4903\\lib\\site-packages\\h5py\\_hl\\files.py\", line 148, in make_fid\n",
      "    fid = h5f.create(name, h5f.ACC_TRUNC, fapl=fapl, fcpl=fcpl)\n",
      "  File \"h5py\\_objects.pyx\", line 54, in h5py._objects.with_phil.wrapper\n",
      "  File \"h5py\\_objects.pyx\", line 55, in h5py._objects.with_phil.wrapper\n",
      "  File \"h5py\\h5f.pyx\", line 98, in h5py.h5f.create\n",
      "OSError: Unable to create file (unable to open file: name = '/home/pi/CPE4903/digit_recog.h5', errno = 2, error message = 'No such file or directory', flags = 13, o_flags = 302)\n",
      "\n",
      "During handling of the above exception, another exception occurred:\n",
      "\n",
      "Traceback (most recent call last):\n",
      "  File \"C:\\Users\\arisj\\anaconda3\\envs\\CPE 4903\\lib\\site-packages\\IPython\\core\\interactiveshell.py\", line 2064, in showtraceback\n",
      "    stb = value._render_traceback_()\n",
      "AttributeError: 'OSError' object has no attribute '_render_traceback_'\n",
      "\n",
      "During handling of the above exception, another exception occurred:\n",
      "\n",
      "Traceback (most recent call last):\n",
      "  File \"C:\\Users\\arisj\\anaconda3\\envs\\CPE 4903\\lib\\site-packages\\IPython\\core\\interactiveshell.py\", line 3364, in run_ast_nodes\n",
      "    if (await self.run_code(code, result,  async_=asy)):\n",
      "  File \"C:\\Users\\arisj\\anaconda3\\envs\\CPE 4903\\lib\\site-packages\\IPython\\core\\interactiveshell.py\", line 3461, in run_code\n",
      "    self.showtraceback(running_compiled_code=True)\n",
      "  File \"C:\\Users\\arisj\\anaconda3\\envs\\CPE 4903\\lib\\site-packages\\IPython\\core\\interactiveshell.py\", line 2067, in showtraceback\n",
      "    value, tb, tb_offset=tb_offset)\n",
      "  File \"C:\\Users\\arisj\\anaconda3\\envs\\CPE 4903\\lib\\site-packages\\IPython\\core\\ultratb.py\", line 1368, in structured_traceback\n",
      "    self, etype, value, tb, tb_offset, number_of_lines_of_context)\n",
      "  File \"C:\\Users\\arisj\\anaconda3\\envs\\CPE 4903\\lib\\site-packages\\IPython\\core\\ultratb.py\", line 1268, in structured_traceback\n",
      "    self, etype, value, tb, tb_offset, number_of_lines_of_context\n",
      "  File \"C:\\Users\\arisj\\anaconda3\\envs\\CPE 4903\\lib\\site-packages\\IPython\\core\\ultratb.py\", line 1125, in structured_traceback\n",
      "    tb_offset)\n",
      "  File \"C:\\Users\\arisj\\anaconda3\\envs\\CPE 4903\\lib\\site-packages\\IPython\\core\\ultratb.py\", line 1082, in format_exception_as_a_whole\n",
      "    last_unique, recursion_repeat = find_recursion(orig_etype, evalue, records)\n",
      "  File \"C:\\Users\\arisj\\anaconda3\\envs\\CPE 4903\\lib\\site-packages\\IPython\\core\\ultratb.py\", line 382, in find_recursion\n",
      "    return len(records), 0\n",
      "TypeError: object of type 'NoneType' has no len()\n",
      "\n",
      "During handling of the above exception, another exception occurred:\n",
      "\n",
      "Traceback (most recent call last):\n",
      "  File \"C:\\Users\\arisj\\anaconda3\\envs\\CPE 4903\\lib\\site-packages\\IPython\\core\\interactiveshell.py\", line 2064, in showtraceback\n",
      "    stb = value._render_traceback_()\n",
      "AttributeError: 'TypeError' object has no attribute '_render_traceback_'\n",
      "\n",
      "During handling of the above exception, another exception occurred:\n",
      "\n",
      "Traceback (most recent call last):\n",
      "  File \"C:\\Users\\arisj\\anaconda3\\envs\\CPE 4903\\lib\\site-packages\\IPython\\core\\interactiveshell.py\", line 2947, in _run_cell\n",
      "    return runner(coro)\n",
      "  File \"C:\\Users\\arisj\\anaconda3\\envs\\CPE 4903\\lib\\site-packages\\IPython\\core\\async_helpers.py\", line 68, in _pseudo_sync_runner\n",
      "    coro.send(None)\n",
      "  File \"C:\\Users\\arisj\\anaconda3\\envs\\CPE 4903\\lib\\site-packages\\IPython\\core\\interactiveshell.py\", line 3173, in run_cell_async\n",
      "    interactivity=interactivity, compiler=compiler, result=result)\n",
      "  File \"C:\\Users\\arisj\\anaconda3\\envs\\CPE 4903\\lib\\site-packages\\IPython\\core\\interactiveshell.py\", line 3383, in run_ast_nodes\n",
      "    self.showtraceback()\n",
      "  File \"C:\\Users\\arisj\\anaconda3\\envs\\CPE 4903\\lib\\site-packages\\IPython\\core\\interactiveshell.py\", line 2067, in showtraceback\n",
      "    value, tb, tb_offset=tb_offset)\n",
      "  File \"C:\\Users\\arisj\\anaconda3\\envs\\CPE 4903\\lib\\site-packages\\IPython\\core\\ultratb.py\", line 1368, in structured_traceback\n",
      "    self, etype, value, tb, tb_offset, number_of_lines_of_context)\n",
      "  File \"C:\\Users\\arisj\\anaconda3\\envs\\CPE 4903\\lib\\site-packages\\IPython\\core\\ultratb.py\", line 1268, in structured_traceback\n",
      "    self, etype, value, tb, tb_offset, number_of_lines_of_context\n",
      "  File \"C:\\Users\\arisj\\anaconda3\\envs\\CPE 4903\\lib\\site-packages\\IPython\\core\\ultratb.py\", line 1143, in structured_traceback\n",
      "    chained_exceptions_tb_offset)\n",
      "  File \"C:\\Users\\arisj\\anaconda3\\envs\\CPE 4903\\lib\\site-packages\\IPython\\core\\ultratb.py\", line 1082, in format_exception_as_a_whole\n",
      "    last_unique, recursion_repeat = find_recursion(orig_etype, evalue, records)\n",
      "  File \"C:\\Users\\arisj\\anaconda3\\envs\\CPE 4903\\lib\\site-packages\\IPython\\core\\ultratb.py\", line 382, in find_recursion\n",
      "    return len(records), 0\n",
      "TypeError: object of type 'NoneType' has no len()\n",
      "\n",
      "During handling of the above exception, another exception occurred:\n",
      "\n",
      "Traceback (most recent call last):\n",
      "  File \"C:\\Users\\arisj\\anaconda3\\envs\\CPE 4903\\lib\\site-packages\\IPython\\core\\interactiveshell.py\", line 2064, in showtraceback\n",
      "    stb = value._render_traceback_()\n",
      "AttributeError: 'TypeError' object has no attribute '_render_traceback_'\n",
      "\n",
      "During handling of the above exception, another exception occurred:\n",
      "\n",
      "Traceback (most recent call last):\n",
      "  File \"C:\\Users\\arisj\\anaconda3\\envs\\CPE 4903\\lib\\site-packages\\IPython\\core\\ultratb.py\", line 1101, in get_records\n",
      "    return _fixed_getinnerframes(etb, number_of_lines_of_context, tb_offset)\n",
      "  File \"C:\\Users\\arisj\\anaconda3\\envs\\CPE 4903\\lib\\site-packages\\IPython\\core\\ultratb.py\", line 248, in wrapped\n",
      "    return f(*args, **kwargs)\n",
      "  File \"C:\\Users\\arisj\\anaconda3\\envs\\CPE 4903\\lib\\site-packages\\IPython\\core\\ultratb.py\", line 281, in _fixed_getinnerframes\n",
      "    records = fix_frame_records_filenames(inspect.getinnerframes(etb, context))\n",
      "  File \"C:\\Users\\arisj\\anaconda3\\envs\\CPE 4903\\lib\\inspect.py\", line 1502, in getinnerframes\n",
      "    frameinfo = (tb.tb_frame,) + getframeinfo(tb, context)\n",
      "  File \"C:\\Users\\arisj\\anaconda3\\envs\\CPE 4903\\lib\\inspect.py\", line 1460, in getframeinfo\n",
      "    filename = getsourcefile(frame) or getfile(frame)\n",
      "  File \"C:\\Users\\arisj\\anaconda3\\envs\\CPE 4903\\lib\\inspect.py\", line 696, in getsourcefile\n",
      "    if getattr(getmodule(object, filename), '__loader__', None) is not None:\n",
      "  File \"C:\\Users\\arisj\\anaconda3\\envs\\CPE 4903\\lib\\inspect.py\", line 733, in getmodule\n",
      "    if ismodule(module) and hasattr(module, '__file__'):\n",
      "  File \"C:\\Users\\arisj\\anaconda3\\envs\\CPE 4903\\lib\\site-packages\\tensorflow\\__init__.py\", line 50, in __getattr__\n",
      "    module = self._load()\n",
      "  File \"C:\\Users\\arisj\\anaconda3\\envs\\CPE 4903\\lib\\site-packages\\tensorflow\\__init__.py\", line 44, in _load\n",
      "    module = _importlib.import_module(self.__name__)\n",
      "  File \"C:\\Users\\arisj\\anaconda3\\envs\\CPE 4903\\lib\\importlib\\__init__.py\", line 127, in import_module\n",
      "    return _bootstrap._gcd_import(name[level:], package, level)\n",
      "  File \"<frozen importlib._bootstrap>\", line 1006, in _gcd_import\n",
      "  File \"<frozen importlib._bootstrap>\", line 983, in _find_and_load\n",
      "  File \"<frozen importlib._bootstrap>\", line 965, in _find_and_load_unlocked\n",
      "ModuleNotFoundError: No module named 'tensorflow_core.estimator'\n"
     ]
    }
   ],
   "source": [
    "import numpy as np\n",
    "from tensorflow import keras\n",
    "from tensorflow.keras import layers\n",
    "\n",
    "# Define shape\n",
    "num_classes = 10\n",
    "input_shape = (28, 28, 1)\n",
    "\n",
    "# Load MNIST data into 2 different sets. one being train and the other being a test set. Each set will need an x and y. \n",
    "(x_train, y_train), (x_test, y_test) = keras.datasets.mnist.load_data()\n",
    "\n",
    "# Reshape and scale data \n",
    "x_train = x_train.reshape(60000, 28, 28, 1)\n",
    "x_test = x_test.reshape(10000, 28, 28, 1)\n",
    "x_train = x_train.astype(\"float32\")/255\n",
    "x_test = x_test.astype(\"float32\")/255\n",
    "\n",
    "# Convert class vectors to binary class matrices\n",
    "y_train = keras.utils.to_categorical(y_train, num_classes)\n",
    "y_test = keras.utils.to_categorical(y_test, num_classes)\n",
    "\n",
    "# Create model with keras: Below there are 2 layers. using the softmax function.\n",
    "model = keras.Sequential(\n",
    "    [\n",
    "        keras.Input(shape=input_shape),\n",
    "        layers.Conv2D(32, kernel_size=(5, 5), activation=\"relu\", data_format=\"channels_last\"),\n",
    "        layers.MaxPooling2D(pool_size=(2, 2)),\n",
    "        layers.Dropout(0.4),\n",
    "        layers.Conv2D(64, kernel_size=(5, 5), activation=\"relu\"),\n",
    "        layers.MaxPooling2D(pool_size=(2, 2)),\n",
    "        layers.Dropout(0.4),\n",
    "        layers.Flatten(),\n",
    "        layers.Dense(units=128, activation='relu'),\n",
    "        layers.Dense(num_classes, activation=\"softmax\"),\n",
    "    ]\n",
    ")\n",
    "\n",
    "model.compile(loss=\"categorical_crossentropy\", optimizer=\"adam\", metrics=[\"accuracy\"])\n",
    "model.summary()\n",
    "\n",
    "# Train model and evaluate performance\n",
    "model.fit(x_train, y_train, batch_size=128, epochs=4)\n",
    "score = model.evaluate(x_test, y_test, verbose=0)\n",
    "print(\"Test loss:\", score[0])\n",
    "print(\"Test accuracy:\", score[1])\n",
    "\n",
    "\n",
    "\n",
    "# Save the newly created model into a file which will be used later \n",
    "model.save('digit_recog.h5')\n"
   ]
  },
  {
   "cell_type": "code",
   "execution_count": 4,
   "id": "34b55c1f",
   "metadata": {},
   "outputs": [],
   "source": []
  },
  {
   "cell_type": "code",
   "execution_count": null,
   "id": "d220d712",
   "metadata": {},
   "outputs": [],
   "source": []
  }
 ],
 "metadata": {
  "kernelspec": {
   "display_name": "Python 3 (ipykernel)",
   "language": "python",
   "name": "python3"
  },
  "language_info": {
   "codemirror_mode": {
    "name": "ipython",
    "version": 3
   },
   "file_extension": ".py",
   "mimetype": "text/x-python",
   "name": "python",
   "nbconvert_exporter": "python",
   "pygments_lexer": "ipython3",
   "version": "3.7.11"
  }
 },
 "nbformat": 4,
 "nbformat_minor": 5
}
